{
  "ablation_study_pipeline": {
    "start_time": "2025-09-09T17:28:27.891008",
    "model_path": "/home/cerlab/Documents/data/pointosr/ckpt/cfgs-train-pointnext-s-ngpus1-seed42-20250824-130842-fzwiyYEtV7a4GyHM2H48rq_ckpt_best.pth",
    "config_path": "/home/cerlab/Documents/pointosr_ws/src/pointosr/pointosr/pointnext/cfgs/pointnext-s.yaml",
    "data_dir": "/home/cerlab/Documents/data/pointosr/dataset",
    "steps": {
      "prototype_generation": {
        "success": true,
        "timestamp": "2025-09-09T17:29:07.257414",
        "output": ""
      },
      "calibration": {
        "success": true,
        "timestamp": "2025-09-09T17:30:13.104849",
        "output": ""
      },
      "evaluation": {
        "success": false,
        "timestamp": "2025-09-09T17:30:31.196478",
        "output": "2025-09-09 17:30:13,720 - INFO - \ud83d\ude80 Starting Ablation Study Evaluation\n2025-09-09 17:30:13,720 - INFO - Model: /home/cerlab/Documents/data/pointosr/ckpt/cfgs-train-pointnext-s-ngpus1-seed42-20250824-130842-fzwiyYEtV7a4GyHM2H48rq_ckpt_best.pth\n2025-09-09 17:30:13,720 - INFO - Config: /home/cerlab/Documents/pointosr_ws/src/pointosr/pointosr/pointnext/cfgs/pointnext-s.yaml\n2025-09-09 17:30:13,720 - INFO - Data: /home/cerlab/Documents/data/pointosr/dataset\n2025-09-09 17:30:13,720 - INFO - Evaluation base: /home/cerlab/Documents/pointosr_ws/src/pointosr/pointosr/osr/evaluation\n2025-09-09 17:30:13,720 - INFO - Running all 9 configurations\n2025-09-09 17:30:13,720 - INFO - \n============================================================\n2025-09-09 17:30:13,720 - INFO - Running evaluation for human_k4_fp_k0\n2025-09-09 17:30:13,720 - INFO - ============================================================\n2025-09-09 17:30:13,720 - INFO - Running command: python3 /home/cerlab/Documents/pointosr_ws/src/pointosr/pointosr/pointnext/classification/osr_eval.py --model_path /home/cerlab/Documents/data/pointosr/ckpt/cfgs-train-pointnext-s-ngpus1-seed42-20250824-130842-fzwiyYEtV7a4GyHM2H48rq_ckpt_best.pth --config_path /home/cerlab/Documents/pointosr_ws/src/pointosr/pointosr/pointnext/cfgs/pointnext-s.yaml --data_dir /home/cerlab/Documents/data/pointosr/dataset --calibration_metadata /home/cerlab/Documents/data/pointosr/dataset/calibration_selection.json --fusion_config_path /home/cerlab/Documents/pointosr_ws/src/pointosr/pointosr/osr/calibration/human_k4_fp_k0/fusion_config.json --stats_path /home/cerlab/Documents/pointosr_ws/src/pointosr/pointosr/osr/calibration/human_k4_fp_k0/stats.json --prototypes_path /home/cerlab/Documents/pointosr_ws/src/pointosr/pointosr/osr/prototypes --output_dir /home/cerlab/Documents/pointosr_ws/src/pointosr/pointosr/osr/evaluation/human_k4_fp_k0 --batch_size 32 --device cuda\n2025-09-09 17:30:15,644 - ERROR - \u274c Evaluation failed for human_k4_fp_k0\n2025-09-09 17:30:15,644 - ERROR - Error output: Traceback (most recent call last):\n  File \"/home/cerlab/Documents/pointosr_ws/src/pointosr/pointosr/pointnext/classification/osr_eval.py\", line 31, in <module>\n    from pointnext.utils import load_checkpoint, setup_logger_dist, set_random_seed\nModuleNotFoundError: No module named 'pointnext'\n\n2025-09-09 17:30:15,644 - INFO - \n============================================================\n2025-09-09 17:30:15,644 - INFO - Running evaluation for human_k4_fp_k1\n2025-09-09 17:30:15,644 - INFO - ============================================================\n2025-09-09 17:30:15,644 - INFO - Running command: python3 /home/cerlab/Documents/pointosr_ws/src/pointosr/pointosr/pointnext/classification/osr_eval.py --model_path /home/cerlab/Documents/data/pointosr/ckpt/cfgs-train-pointnext-s-ngpus1-seed42-20250824-130842-fzwiyYEtV7a4GyHM2H48rq_ckpt_best.pth --config_path /home/cerlab/Documents/pointosr_ws/src/pointosr/pointosr/pointnext/cfgs/pointnext-s.yaml --data_dir /home/cerlab/Documents/data/pointosr/dataset --calibration_metadata /home/cerlab/Documents/data/pointosr/dataset/calibration_selection.json --fusion_config_path /home/cerlab/Documents/pointosr_ws/src/pointosr/pointosr/osr/calibration/human_k4_fp_k1/fusion_config.json --stats_path /home/cerlab/Documents/pointosr_ws/src/pointosr/pointosr/osr/calibration/human_k4_fp_k1/stats.json --prototypes_path /home/cerlab/Documents/pointosr_ws/src/pointosr/pointosr/osr/prototypes --output_dir /home/cerlab/Documents/pointosr_ws/src/pointosr/pointosr/osr/evaluation/human_k4_fp_k1 --batch_size 32 --device cuda\n2025-09-09 17:30:17,579 - ERROR - \u274c Evaluation failed for human_k4_fp_k1\n2025-09-09 17:30:17,579 - ERROR - Error output: Traceback (most recent call last):\n  File \"/home/cerlab/Documents/pointosr_ws/src/pointosr/pointosr/pointnext/classification/osr_eval.py\", line 31, in <module>\n    from pointnext.utils import load_checkpoint, setup_logger_dist, set_random_seed\nModuleNotFoundError: No module named 'pointnext'\n\n2025-09-09 17:30:17,579 - INFO - \n============================================================\n2025-09-09 17:30:17,579 - INFO - Running evaluation for human_k4_fp_k2\n2025-09-09 17:30:17,579 - INFO - ============================================================\n2025-09-09 17:30:17,579 - INFO - Running command: python3 /home/cerlab/Documents/pointosr_ws/src/pointosr/pointosr/pointnext/classification/osr_eval.py --model_path /home/cerlab/Documents/data/pointosr/ckpt/cfgs-train-pointnext-s-ngpus1-seed42-20250824-130842-fzwiyYEtV7a4GyHM2H48rq_ckpt_best.pth --config_path /home/cerlab/Documents/pointosr_ws/src/pointosr/pointosr/pointnext/cfgs/pointnext-s.yaml --data_dir /home/cerlab/Documents/data/pointosr/dataset --calibration_metadata /home/cerlab/Documents/data/pointosr/dataset/calibration_selection.json --fusion_config_path /home/cerlab/Documents/pointosr_ws/src/pointosr/pointosr/osr/calibration/human_k4_fp_k2/fusion_config.json --stats_path /home/cerlab/Documents/pointosr_ws/src/pointosr/pointosr/osr/calibration/human_k4_fp_k2/stats.json --prototypes_path /home/cerlab/Documents/pointosr_ws/src/pointosr/pointosr/osr/prototypes --output_dir /home/cerlab/Documents/pointosr_ws/src/pointosr/pointosr/osr/evaluation/human_k4_fp_k2 --batch_size 32 --device cuda\n2025-09-09 17:30:19,480 - ERROR - \u274c Evaluation failed for human_k4_fp_k2\n2025-09-09 17:30:19,480 - ERROR - Error output: Traceback (most recent call last):\n  File \"/home/cerlab/Documents/pointosr_ws/src/pointosr/pointosr/pointnext/classification/osr_eval.py\", line 31, in <module>\n    from pointnext.utils import load_checkpoint, setup_logger_dist, set_random_seed\nModuleNotFoundError: No module named 'pointnext'\n\n2025-09-09 17:30:19,480 - INFO - \n============================================================\n2025-09-09 17:30:19,480 - INFO - Running evaluation for human_k8_fp_k0\n2025-09-09 17:30:19,480 - INFO - ============================================================\n2025-09-09 17:30:19,480 - INFO - Running command: python3 /home/cerlab/Documents/pointosr_ws/src/pointosr/pointosr/pointnext/classification/osr_eval.py --model_path /home/cerlab/Documents/data/pointosr/ckpt/cfgs-train-pointnext-s-ngpus1-seed42-20250824-130842-fzwiyYEtV7a4GyHM2H48rq_ckpt_best.pth --config_path /home/cerlab/Documents/pointosr_ws/src/pointosr/pointosr/pointnext/cfgs/pointnext-s.yaml --data_dir /home/cerlab/Documents/data/pointosr/dataset --calibration_metadata /home/cerlab/Documents/data/pointosr/dataset/calibration_selection.json --fusion_config_path /home/cerlab/Documents/pointosr_ws/src/pointosr/pointosr/osr/calibration/human_k8_fp_k0/fusion_config.json --stats_path /home/cerlab/Documents/pointosr_ws/src/pointosr/pointosr/osr/calibration/human_k8_fp_k0/stats.json --prototypes_path /home/cerlab/Documents/pointosr_ws/src/pointosr/pointosr/osr/prototypes --output_dir /home/cerlab/Documents/pointosr_ws/src/pointosr/pointosr/osr/evaluation/human_k8_fp_k0 --batch_size 32 --device cuda\n2025-09-09 17:30:21,409 - ERROR - \u274c Evaluation failed for human_k8_fp_k0\n2025-09-09 17:30:21,409 - ERROR - Error output: Traceback (most recent call last):\n  File \"/home/cerlab/Documents/pointosr_ws/src/pointosr/pointosr/pointnext/classification/osr_eval.py\", line 31, in <module>\n    from pointnext.utils import load_checkpoint, setup_logger_dist, set_random_seed\nModuleNotFoundError: No module named 'pointnext'\n\n2025-09-09 17:30:21,409 - INFO - \n============================================================\n2025-09-09 17:30:21,409 - INFO - Running evaluation for human_k8_fp_k1\n2025-09-09 17:30:21,409 - INFO - ============================================================\n2025-09-09 17:30:21,409 - INFO - Running command: python3 /home/cerlab/Documents/pointosr_ws/src/pointosr/pointosr/pointnext/classification/osr_eval.py --model_path /home/cerlab/Documents/data/pointosr/ckpt/cfgs-train-pointnext-s-ngpus1-seed42-20250824-130842-fzwiyYEtV7a4GyHM2H48rq_ckpt_best.pth --config_path /home/cerlab/Documents/pointosr_ws/src/pointosr/pointosr/pointnext/cfgs/pointnext-s.yaml --data_dir /home/cerlab/Documents/data/pointosr/dataset --calibration_metadata /home/cerlab/Documents/data/pointosr/dataset/calibration_selection.json --fusion_config_path /home/cerlab/Documents/pointosr_ws/src/pointosr/pointosr/osr/calibration/human_k8_fp_k1/fusion_config.json --stats_path /home/cerlab/Documents/pointosr_ws/src/pointosr/pointosr/osr/calibration/human_k8_fp_k1/stats.json --prototypes_path /home/cerlab/Documents/pointosr_ws/src/pointosr/pointosr/osr/prototypes --output_dir /home/cerlab/Documents/pointosr_ws/src/pointosr/pointosr/osr/evaluation/human_k8_fp_k1 --batch_size 32 --device cuda\n2025-09-09 17:30:23,338 - ERROR - \u274c Evaluation failed for human_k8_fp_k1\n2025-09-09 17:30:23,338 - ERROR - Error output: Traceback (most recent call last):\n  File \"/home/cerlab/Documents/pointosr_ws/src/pointosr/pointosr/pointnext/classification/osr_eval.py\", line 31, in <module>\n    from pointnext.utils import load_checkpoint, setup_logger_dist, set_random_seed\nModuleNotFoundError: No module named 'pointnext'\n\n2025-09-09 17:30:23,338 - INFO - \n============================================================\n2025-09-09 17:30:23,338 - INFO - Running evaluation for human_k8_fp_k2\n2025-09-09 17:30:23,338 - INFO - ============================================================\n2025-09-09 17:30:23,338 - INFO - Running command: python3 /home/cerlab/Documents/pointosr_ws/src/pointosr/pointosr/pointnext/classification/osr_eval.py --model_path /home/cerlab/Documents/data/pointosr/ckpt/cfgs-train-pointnext-s-ngpus1-seed42-20250824-130842-fzwiyYEtV7a4GyHM2H48rq_ckpt_best.pth --config_path /home/cerlab/Documents/pointosr_ws/src/pointosr/pointosr/pointnext/cfgs/pointnext-s.yaml --data_dir /home/cerlab/Documents/data/pointosr/dataset --calibration_metadata /home/cerlab/Documents/data/pointosr/dataset/calibration_selection.json --fusion_config_path /home/cerlab/Documents/pointosr_ws/src/pointosr/pointosr/osr/calibration/human_k8_fp_k2/fusion_config.json --stats_path /home/cerlab/Documents/pointosr_ws/src/pointosr/pointosr/osr/calibration/human_k8_fp_k2/stats.json --prototypes_path /home/cerlab/Documents/pointosr_ws/src/pointosr/pointosr/osr/prototypes --output_dir /home/cerlab/Documents/pointosr_ws/src/pointosr/pointosr/osr/evaluation/human_k8_fp_k2 --batch_size 32 --device cuda\n2025-09-09 17:30:25,285 - ERROR - \u274c Evaluation failed for human_k8_fp_k2\n2025-09-09 17:30:25,285 - ERROR - Error output: Traceback (most recent call last):\n  File \"/home/cerlab/Documents/pointosr_ws/src/pointosr/pointosr/pointnext/classification/osr_eval.py\", line 31, in <module>\n    from pointnext.utils import load_checkpoint, setup_logger_dist, set_random_seed\nModuleNotFoundError: No module named 'pointnext'\n\n2025-09-09 17:30:25,285 - INFO - \n============================================================\n2025-09-09 17:30:25,285 - INFO - Running evaluation for human_k16_fp_k0\n2025-09-09 17:30:25,285 - INFO - ============================================================\n2025-09-09 17:30:25,285 - INFO - Running command: python3 /home/cerlab/Documents/pointosr_ws/src/pointosr/pointosr/pointnext/classification/osr_eval.py --model_path /home/cerlab/Documents/data/pointosr/ckpt/cfgs-train-pointnext-s-ngpus1-seed42-20250824-130842-fzwiyYEtV7a4GyHM2H48rq_ckpt_best.pth --config_path /home/cerlab/Documents/pointosr_ws/src/pointosr/pointosr/pointnext/cfgs/pointnext-s.yaml --data_dir /home/cerlab/Documents/data/pointosr/dataset --calibration_metadata /home/cerlab/Documents/data/pointosr/dataset/calibration_selection.json --fusion_config_path /home/cerlab/Documents/pointosr_ws/src/pointosr/pointosr/osr/calibration/human_k16_fp_k0/fusion_config.json --stats_path /home/cerlab/Documents/pointosr_ws/src/pointosr/pointosr/osr/calibration/human_k16_fp_k0/stats.json --prototypes_path /home/cerlab/Documents/pointosr_ws/src/pointosr/pointosr/osr/prototypes --output_dir /home/cerlab/Documents/pointosr_ws/src/pointosr/pointosr/osr/evaluation/human_k16_fp_k0 --batch_size 32 --device cuda\n2025-09-09 17:30:27,213 - ERROR - \u274c Evaluation failed for human_k16_fp_k0\n2025-09-09 17:30:27,213 - ERROR - Error output: Traceback (most recent call last):\n  File \"/home/cerlab/Documents/pointosr_ws/src/pointosr/pointosr/pointnext/classification/osr_eval.py\", line 31, in <module>\n    from pointnext.utils import load_checkpoint, setup_logger_dist, set_random_seed\nModuleNotFoundError: No module named 'pointnext'\n\n2025-09-09 17:30:27,213 - INFO - \n============================================================\n2025-09-09 17:30:27,213 - INFO - Running evaluation for human_k16_fp_k1\n2025-09-09 17:30:27,213 - INFO - ============================================================\n2025-09-09 17:30:27,213 - INFO - Running command: python3 /home/cerlab/Documents/pointosr_ws/src/pointosr/pointosr/pointnext/classification/osr_eval.py --model_path /home/cerlab/Documents/data/pointosr/ckpt/cfgs-train-pointnext-s-ngpus1-seed42-20250824-130842-fzwiyYEtV7a4GyHM2H48rq_ckpt_best.pth --config_path /home/cerlab/Documents/pointosr_ws/src/pointosr/pointosr/pointnext/cfgs/pointnext-s.yaml --data_dir /home/cerlab/Documents/data/pointosr/dataset --calibration_metadata /home/cerlab/Documents/data/pointosr/dataset/calibration_selection.json --fusion_config_path /home/cerlab/Documents/pointosr_ws/src/pointosr/pointosr/osr/calibration/human_k16_fp_k1/fusion_config.json --stats_path /home/cerlab/Documents/pointosr_ws/src/pointosr/pointosr/osr/calibration/human_k16_fp_k1/stats.json --prototypes_path /home/cerlab/Documents/pointosr_ws/src/pointosr/pointosr/osr/prototypes --output_dir /home/cerlab/Documents/pointosr_ws/src/pointosr/pointosr/osr/evaluation/human_k16_fp_k1 --batch_size 32 --device cuda\n2025-09-09 17:30:29,197 - ERROR - \u274c Evaluation failed for human_k16_fp_k1\n2025-09-09 17:30:29,197 - ERROR - Error output: Traceback (most recent call last):\n  File \"/home/cerlab/Documents/pointosr_ws/src/pointosr/pointosr/pointnext/classification/osr_eval.py\", line 31, in <module>\n    from pointnext.utils import load_checkpoint, setup_logger_dist, set_random_seed\nModuleNotFoundError: No module named 'pointnext'\n\n2025-09-09 17:30:29,197 - INFO - \n============================================================\n2025-09-09 17:30:29,197 - INFO - Running evaluation for human_k16_fp_k2\n2025-09-09 17:30:29,197 - INFO - ============================================================\n2025-09-09 17:30:29,197 - INFO - Running command: python3 /home/cerlab/Documents/pointosr_ws/src/pointosr/pointosr/pointnext/classification/osr_eval.py --model_path /home/cerlab/Documents/data/pointosr/ckpt/cfgs-train-pointnext-s-ngpus1-seed42-20250824-130842-fzwiyYEtV7a4GyHM2H48rq_ckpt_best.pth --config_path /home/cerlab/Documents/pointosr_ws/src/pointosr/pointosr/pointnext/cfgs/pointnext-s.yaml --data_dir /home/cerlab/Documents/data/pointosr/dataset --calibration_metadata /home/cerlab/Documents/data/pointosr/dataset/calibration_selection.json --fusion_config_path /home/cerlab/Documents/pointosr_ws/src/pointosr/pointosr/osr/calibration/human_k16_fp_k2/fusion_config.json --stats_path /home/cerlab/Documents/pointosr_ws/src/pointosr/pointosr/osr/calibration/human_k16_fp_k2/stats.json --prototypes_path /home/cerlab/Documents/pointosr_ws/src/pointosr/pointosr/osr/prototypes --output_dir /home/cerlab/Documents/pointosr_ws/src/pointosr/pointosr/osr/evaluation/human_k16_fp_k2 --batch_size 32 --device cuda\n2025-09-09 17:30:31,151 - ERROR - \u274c Evaluation failed for human_k16_fp_k2\n2025-09-09 17:30:31,151 - ERROR - Error output: Traceback (most recent call last):\n  File \"/home/cerlab/Documents/pointosr_ws/src/pointosr/pointosr/pointnext/classification/osr_eval.py\", line 31, in <module>\n    from pointnext.utils import load_checkpoint, setup_logger_dist, set_random_seed\nModuleNotFoundError: No module named 'pointnext'\n\n2025-09-09 17:30:31,151 - INFO - \n\ud83d\udcca Collecting evaluation results...\n2025-09-09 17:30:31,152 - WARNING - No evaluation results found for human_k4_fp_k0\n2025-09-09 17:30:31,152 - WARNING - No evaluation results found for human_k4_fp_k1\n2025-09-09 17:30:31,152 - WARNING - No evaluation results found for human_k4_fp_k2\n2025-09-09 17:30:31,152 - WARNING - No evaluation results found for human_k8_fp_k0\n2025-09-09 17:30:31,152 - WARNING - No evaluation results found for human_k8_fp_k1\n2025-09-09 17:30:31,152 - WARNING - No evaluation results found for human_k8_fp_k2\n2025-09-09 17:30:31,152 - WARNING - No evaluation results found for human_k16_fp_k0\n2025-09-09 17:30:31,152 - WARNING - No evaluation results found for human_k16_fp_k1\n2025-09-09 17:30:31,152 - WARNING - No evaluation results found for human_k16_fp_k2\n2025-09-09 17:30:31,152 - WARNING - No comparison data available\n2025-09-09 17:30:31,152 - INFO - \n============================================================\n2025-09-09 17:30:31,152 - INFO - \ud83c\udf89 Ablation Study Evaluation Completed!\n2025-09-09 17:30:31,152 - INFO - Total configurations: 9\n2025-09-09 17:30:31,152 - INFO - Successful: 0\n2025-09-09 17:30:31,152 - INFO - Failed: 9\n2025-09-09 17:30:31,152 - INFO - Results with comparison data: 0\n2025-09-09 17:30:31,152 - INFO - \u274c Failed configurations:\n2025-09-09 17:30:31,152 - INFO -   - human_k4_fp_k0\n2025-09-09 17:30:31,152 - INFO -   - human_k4_fp_k1\n2025-09-09 17:30:31,152 - INFO -   - human_k4_fp_k2\n2025-09-09 17:30:31,152 - INFO -   - human_k8_fp_k0\n2025-09-09 17:30:31,152 - INFO -   - human_k8_fp_k1\n2025-09-09 17:30:31,152 - INFO -   - human_k8_fp_k2\n2025-09-09 17:30:31,152 - INFO -   - human_k16_fp_k0\n2025-09-09 17:30:31,152 - INFO -   - human_k16_fp_k1\n2025-09-09 17:30:31,152 - INFO -   - human_k16_fp_k2\n2025-09-09 17:30:31,152 - INFO - Results summary saved to: /home/cerlab/Documents/pointosr_ws/src/pointosr/pointosr/osr/evaluation/ablation_evaluation_summary.json\n2025-09-09 17:30:31,152 - INFO - Comparison report saved to: /home/cerlab/Documents/pointosr_ws/src/pointosr/pointosr/osr/evaluation/ablation_evaluation_comparison.json\n2025-09-09 17:30:31,152 - INFO - ============================================================\n"
      }
    },
    "end_time": "2025-09-09T17:30:31.196535"
  }
}